2018-07-29 15:01:16,559 INFO: Microblog startup [in /Users/user/Dropbox/Python/Flask-app/microblog/app/__init__.py:74]
2018-07-29 15:01:21,573 ERROR: Exception on / [GET] [in /Users/user/anaconda3/envs/flask-app/lib/python3.6/site-packages/flask/app.py:1560]
Traceback (most recent call last):
  File "/Users/user/anaconda3/envs/flask-app/lib/python3.6/site-packages/sqlalchemy/engine/base.py", line 1193, in _execute_context
    context)
  File "/Users/user/anaconda3/envs/flask-app/lib/python3.6/site-packages/sqlalchemy/engine/default.py", line 508, in do_execute
    cursor.execute(statement, parameters)
sqlite3.OperationalError: no such table: user

The above exception was the direct cause of the following exception:

Traceback (most recent call last):
  File "/Users/user/anaconda3/envs/flask-app/lib/python3.6/site-packages/flask/app.py", line 1982, in wsgi_app
    response = self.full_dispatch_request()
  File "/Users/user/anaconda3/envs/flask-app/lib/python3.6/site-packages/flask/app.py", line 1614, in full_dispatch_request
    rv = self.handle_user_exception(e)
  File "/Users/user/anaconda3/envs/flask-app/lib/python3.6/site-packages/flask/app.py", line 1517, in handle_user_exception
    reraise(exc_type, exc_value, tb)
  File "/Users/user/anaconda3/envs/flask-app/lib/python3.6/site-packages/flask/_compat.py", line 33, in reraise
    raise value
  File "/Users/user/anaconda3/envs/flask-app/lib/python3.6/site-packages/flask/app.py", line 1610, in full_dispatch_request
    rv = self.preprocess_request()
  File "/Users/user/anaconda3/envs/flask-app/lib/python3.6/site-packages/flask/app.py", line 1831, in preprocess_request
    rv = func()
  File "/Users/user/Dropbox/Python/Flask-app/microblog/app/main/routes.py", line 16, in before_request
    if current_user.is_authenticated:
  File "/Users/user/anaconda3/envs/flask-app/lib/python3.6/site-packages/werkzeug/local.py", line 347, in __getattr__
    return getattr(self._get_current_object(), name)
  File "/Users/user/anaconda3/envs/flask-app/lib/python3.6/site-packages/werkzeug/local.py", line 306, in _get_current_object
    return self.__local()
  File "/Users/user/anaconda3/envs/flask-app/lib/python3.6/site-packages/flask_login/utils.py", line 26, in <lambda>
    current_user = LocalProxy(lambda: _get_user())
  File "/Users/user/anaconda3/envs/flask-app/lib/python3.6/site-packages/flask_login/utils.py", line 335, in _get_user
    current_app.login_manager._load_user()
  File "/Users/user/anaconda3/envs/flask-app/lib/python3.6/site-packages/flask_login/login_manager.py", line 353, in _load_user
    return self._load_from_cookie(request.cookies[cookie_name])
  File "/Users/user/anaconda3/envs/flask-app/lib/python3.6/site-packages/flask_login/login_manager.py", line 392, in _load_from_cookie
    self.reload_user()
  File "/Users/user/anaconda3/envs/flask-app/lib/python3.6/site-packages/flask_login/login_manager.py", line 321, in reload_user
    user = self.user_callback(user_id)
  File "/Users/user/Dropbox/Python/Flask-app/microblog/app/models.py", line 83, in load_user
    return User.query.get(int(id))
  File "/Users/user/anaconda3/envs/flask-app/lib/python3.6/site-packages/sqlalchemy/orm/query.py", line 887, in get
    ident, loading.load_on_pk_identity)
  File "/Users/user/anaconda3/envs/flask-app/lib/python3.6/site-packages/sqlalchemy/orm/query.py", line 962, in _get_impl
    return db_load_fn(self, primary_key_identity)
  File "/Users/user/anaconda3/envs/flask-app/lib/python3.6/site-packages/sqlalchemy/orm/loading.py", line 250, in load_on_pk_identity
    return q.one()
  File "/Users/user/anaconda3/envs/flask-app/lib/python3.6/site-packages/sqlalchemy/orm/query.py", line 2894, in one
    ret = self.one_or_none()
  File "/Users/user/anaconda3/envs/flask-app/lib/python3.6/site-packages/sqlalchemy/orm/query.py", line 2864, in one_or_none
    ret = list(self)
  File "/Users/user/anaconda3/envs/flask-app/lib/python3.6/site-packages/sqlalchemy/orm/query.py", line 2935, in __iter__
    return self._execute_and_instances(context)
  File "/Users/user/anaconda3/envs/flask-app/lib/python3.6/site-packages/sqlalchemy/orm/query.py", line 2958, in _execute_and_instances
    result = conn.execute(querycontext.statement, self._params)
  File "/Users/user/anaconda3/envs/flask-app/lib/python3.6/site-packages/sqlalchemy/engine/base.py", line 948, in execute
    return meth(self, multiparams, params)
  File "/Users/user/anaconda3/envs/flask-app/lib/python3.6/site-packages/sqlalchemy/sql/elements.py", line 269, in _execute_on_connection
    return connection._execute_clauseelement(self, multiparams, params)
  File "/Users/user/anaconda3/envs/flask-app/lib/python3.6/site-packages/sqlalchemy/engine/base.py", line 1060, in _execute_clauseelement
    compiled_sql, distilled_params
  File "/Users/user/anaconda3/envs/flask-app/lib/python3.6/site-packages/sqlalchemy/engine/base.py", line 1200, in _execute_context
    context)
  File "/Users/user/anaconda3/envs/flask-app/lib/python3.6/site-packages/sqlalchemy/engine/base.py", line 1413, in _handle_dbapi_exception
    exc_info
  File "/Users/user/anaconda3/envs/flask-app/lib/python3.6/site-packages/sqlalchemy/util/compat.py", line 203, in raise_from_cause
    reraise(type(exception), exception, tb=exc_tb, cause=cause)
  File "/Users/user/anaconda3/envs/flask-app/lib/python3.6/site-packages/sqlalchemy/util/compat.py", line 186, in reraise
    raise value.with_traceback(tb)
  File "/Users/user/anaconda3/envs/flask-app/lib/python3.6/site-packages/sqlalchemy/engine/base.py", line 1193, in _execute_context
    context)
  File "/Users/user/anaconda3/envs/flask-app/lib/python3.6/site-packages/sqlalchemy/engine/default.py", line 508, in do_execute
    cursor.execute(statement, parameters)
sqlalchemy.exc.OperationalError: (sqlite3.OperationalError) no such table: user [SQL: 'SELECT user.id AS user_id, user.username AS user_username, user.email AS user_email, user.password_hash AS user_password_hash, user.about_me AS user_about_me, user.last_seen AS user_last_seen \nFROM user \nWHERE user.id = ?'] [parameters: (9,)] (Background on this error at: http://sqlalche.me/e/e3q8)
